<?xml version="1.0" encoding="utf-8"?>
<robot name="robot" xmlns:xacro="http://www.ros.org/wiki/xacro">

  <gazebo>
    <plugin name="gazebo_ros_control" filename="libgazebo_ros_control.so">
      <robotNamespace>/omnirobot</robotNamespace>
    </plugin>
  </gazebo>

  <link name="base_link">
    <visual>
      <geometry>
        <mesh filename="package://holonome_description/meshes/Bati.stl"/>
      </geometry>
      <origin xyz="0 0 0" rpy="${pi/2} 0 ${pi/2 + 2*pi/3}"/>
    </visual>

    <collision>
      <geometry>
        <mesh filename="package://holonome_description/meshes/Bati.stl"/>
      </geometry>
      <origin xyz="0 0 0" rpy="${pi/2} 0 ${pi/2 + 2*pi/3}"/>
    </collision>

    <!--
    <inertial>
      <origin xyz="0.0 0 0."/>
      <mass value="0.5"/> 
      <inertia ixx="0.01" ixy="0.0" ixz="0.0"
                iyy="0.01" iyz="0.0" 
                izz="0.03" />
    </inertial>
    -->
  </link>

  

  <link name="wheel_front">
    <visual>
      <geometry>
        <mesh filename="package://holonome_description/meshes/roue.stl"/>
      </geometry>
      <origin xyz="0 0 0" rpy="0 ${pi/2} 0"/>
    </visual>
    <collision>
      <geometry>
        <mesh filename="package://holonome_description/meshes/roue.stl"/>
      </geometry>
      <origin xyz="117.2 0 -21.4" rpy="0 ${pi/2} 0"/>
    </collision>
    <!--
    <inertial>
      <origin xyz="0.0 0 0."/>
      <mass value="0.5"/> 
      <inertia ixx="0.01" ixy="0.0" ixz="0.0"
                iyy="0.01" iyz="0.0" 
                izz="0.03" />
    </inertial>
    -->
  </link>

  <joint name="wheel_front_joint" type="continuous">
    <parent link="base_link"/>
    <child link="wheel_front"/>
    <origin xyz="117.2 0 -21.4" rpy="0 0 0"/>
    <axis xyz="1 0 0"/>
  </joint>

  <joint name="rouleau_front1_joint" type="continuous">
    <parent link="wheel_front"/>
    <child link="rouleau_front1"/>
    <origin xyz="7.4 12.24 -12.24" rpy="0 0 0"/>
    <axis xyz="0 1 1"/>
  </joint>
  <link name="rouleau_front1">
    <visual>
      <geometry>
        <mesh filename="package://holonome_description/meshes/rouleau.stl"/>
      </geometry>
      <origin xyz="0 0 0" rpy="0 ${pi/4} ${-pi/2}"/>
    </visual>
    <collision>
      <geometry>
        <mesh filename="package://holonome_description/meshes/rouleau.stl"/>
      </geometry>
      <origin xyz="0 0 0" rpy="0 ${pi/4} ${-pi/2}"/>
    </collision>
  </link>

  <joint name="rouleau_front2_joint" type="continuous">
    <parent link="wheel_front"/>
    <child link="rouleau_front2"/>
    <origin xyz="7.4 -12.24 -12.24" rpy="0 0 0"/>
    <axis xyz="0 1 -1"/>
  </joint>
  <link name="rouleau_front2">
    <visual>
      <geometry>
        <mesh filename="package://holonome_description/meshes/rouleau.stl"/>
      </geometry>
      <origin xyz="0 0 0" rpy="0 ${-pi/4} ${-pi/2}"/>
    </visual>
    <collision>
      <geometry>
        <mesh filename="package://holonome_description/meshes/rouleau.stl"/>
      </geometry>
      <origin xyz="0 0 0" rpy="0 ${-pi/4} ${-pi/2}"/>
    </collision>
  </link>

  <joint name="rouleau_front3_joint" type="continuous">
    <parent link="wheel_front"/>
    <child link="rouleau_front3"/>
    <origin xyz="7.4 -12.24 12.24" rpy="0 0 0"/>
    <axis xyz="0 1 1"/>
  </joint>
  <link name="rouleau_front3">
    <visual>
      <geometry>
        <mesh filename="package://holonome_description/meshes/rouleau.stl"/>
      </geometry>
      <origin xyz="0 0 0" rpy="0 ${pi/4} ${-pi/2}"/>
    </visual>
    <collision>
      <geometry>
        <mesh filename="package://holonome_description/meshes/rouleau.stl"/>
      </geometry>
      <origin xyz="0 0 0" rpy="0 ${pi/4} ${-pi/2}"/>
    </collision>
  </link>

  <joint name="rouleau_front4_joint" type="continuous">
    <parent link="wheel_front"/>
    <child link="rouleau_front4"/>
    <origin xyz="7.4 12.24 12.24" rpy="0 0 0"/>
    <axis xyz="0 1 -1"/>
  </joint>
  <link name="rouleau_front4">
    <visual>
      <geometry>
        <mesh filename="package://holonome_description/meshes/rouleau.stl"/>
      </geometry>
      <origin xyz="0 0 0" rpy="0 ${-pi/4} ${-pi/2}"/>
    </visual>
    <collision>
      <geometry>
        <mesh filename="package://holonome_description/meshes/rouleau.stl"/>
      </geometry>
      <origin xyz="0 0 0" rpy="0 ${pi/4} ${-pi/2}"/>
    </collision>
  </link>
  
  <joint name="rouleau_front5_joint" type="continuous">
    <parent link="wheel_front"/>
    <child link="rouleau_front5"/>
    <origin xyz="-3.8 0 17.31" rpy="0 0 0"/>
    <axis xyz="0 1 0"/>
  </joint>
  <link name="rouleau_front5">
    <visual>
      <geometry>
        <mesh filename="package://holonome_description/meshes/rouleau.stl"/>
      </geometry>
      <origin xyz="0 0 0" rpy="0 0 ${pi/2}"/>
    </visual>
    <collision>
      <geometry>
        <mesh filename="package://holonome_description/meshes/rouleau.stl"/>
      </geometry>
      <origin xyz="0 0 0" rpy="0 0 ${pi/2}"/>
    </collision>
  </link>

  <joint name="rouleau_front6_joint" type="continuous">
    <parent link="wheel_front"/>
    <child link="rouleau_front6"/>
    <origin xyz="-3.8 17.31 0" rpy="0 0 0"/>
    <axis xyz="0 0 1"/>
  </joint>
  <link name="rouleau_front6">
    <visual>
      <geometry>
        <mesh filename="package://holonome_description/meshes/rouleau.stl"/>
      </geometry>
      <origin xyz="0 0 0" rpy="0 ${pi/2} 0"/>
    </visual>
    <collision>
      <geometry>
        <mesh filename="package://holonome_description/meshes/rouleau.stl"/>
      </geometry>
      <origin xyz="0 0 0" rpy="0 ${pi/2} 0"/>
    </collision>
  </link>

  <joint name="rouleau_front7_joint" type="continuous">
    <parent link="wheel_front"/>
    <child link="rouleau_front7"/>
    <origin xyz="-3.8 0 -17.31" rpy="0 0 0"/>
    <axis xyz="0 1 0"/>
  </joint>
  <link name="rouleau_front7">
    <visual>
      <geometry>
        <mesh filename="package://holonome_description/meshes/rouleau.stl"/>
      </geometry>
      <origin xyz="0 0 0" rpy="0 0 ${pi/2}"/>
    </visual>
    <collision>
      <geometry>
        <mesh filename="package://holonome_description/meshes/rouleau.stl"/>
      </geometry>
      <origin xyz="0 0 0" rpy="0 0 ${pi/2}"/>
    </collision>
  </link>

  <joint name="rouleau_front8_joint" type="continuous">
    <parent link="wheel_front"/>
    <child link="rouleau_front8"/>
    <origin xyz="-3.8 -17.31 0" rpy="0 0 0"/>
    <axis xyz="0 0 1"/>
  </joint>
  <link name="rouleau_front8">
    <visual>
      <geometry>
        <mesh filename="package://holonome_description/meshes/rouleau.stl"/>
      </geometry>
      <origin xyz="0 0 0" rpy="0 ${pi/2} 0"/>
    </visual>
    <collision>
      <geometry>
        <mesh filename="package://holonome_description/meshes/rouleau.stl"/>
      </geometry>
      <origin xyz="0 0 0" rpy="0 ${pi/2} 0"/>
    </collision>
  </link>

  <joint name="wheel_left_joint" type="continuous">
    <parent link="base_link"/>
    <child link="wheel_left"/>
    <origin xyz="-58.6 101.5 -21.4" rpy="0 0 ${pi*2/3}"/>
    <axis xyz="${cos(pi*2/3)} ${sin(pi*2/3)} 0"/>
  </joint>

  <link name="wheel_left">
    <visual>
      <geometry>
        <mesh filename="package://holonome_description/meshes/roue.stl"/>
      </geometry>
      <origin xyz="0 0 0" rpy="0 ${pi/2} 0"/>
    </visual>
    <collision>
      <geometry>
        <mesh filename="package://holonome_description/meshes/roue.stl"/>
      </geometry>
      <origin xyz="0 0 0" rpy="0 ${pi/2} 0"/>
    </collision>
    <!--
    <inertial>
      <origin xyz="0.0 0 0."/>
      <mass value="0.5"/> 
      <inertia ixx="0.01" ixy="0.0" ixz="0.0"
                iyy="0.01" iyz="0.0" 
                izz="0.03" />
    </inertial>
    -->
  </link>


  <joint name="rouleau_left1_joint" type="continuous">
    <parent link="wheel_left"/>
    <child link="rouleau_left1"/>
    <origin xyz="7.4 12.24 -12.24" rpy="0 0 0"/>
    <axis xyz="0 1 1"/>
  </joint>
  <link name="rouleau_left1">
    <visual>
      <geometry>
        <mesh filename="package://holonome_description/meshes/rouleau.stl"/>
      </geometry>
      <origin xyz="0 0 0" rpy="0 ${pi/4} ${-pi/2}"/>
    </visual>
    <collision>
      <geometry>
        <mesh filename="package://holonome_description/meshes/rouleau.stl"/>
      </geometry>
      <origin xyz="0 0 0" rpy="0 ${pi/4} ${-pi/2}"/>
    </collision>
  </link>

  <joint name="rouleau_left2_joint" type="continuous">
    <parent link="wheel_left"/>
    <child link="rouleau_left2"/>
    <origin xyz="7.4 -12.24 -12.24" rpy="0 0 0"/>
    <axis xyz="0 1 -1"/>
  </joint>
  <link name="rouleau_left2">
    <visual>
      <geometry>
        <mesh filename="package://holonome_description/meshes/rouleau.stl"/>
      </geometry>
      <origin xyz="0 0 0" rpy="0 ${-pi/4} ${-pi/2}"/>
    </visual>
    <collision>
      <geometry>
        <mesh filename="package://holonome_description/meshes/rouleau.stl"/>
      </geometry>
      <origin xyz="0 0 0" rpy="0 ${-pi/4} ${-pi/2}"/>
    </collision>
  </link>

  <joint name="rouleau_left3_joint" type="continuous">
    <parent link="wheel_left"/>
    <child link="rouleau_left3"/>
    <origin xyz="7.4 -12.24 12.24" rpy="0 0 0"/>
    <axis xyz="0 1 1"/>
  </joint>
  <link name="rouleau_left3">
    <visual>
      <geometry>
        <mesh filename="package://holonome_description/meshes/rouleau.stl"/>
      </geometry>
      <origin xyz="0 0 0" rpy="0 ${pi/4} ${-pi/2}"/>
    </visual>
    <collision>
      <geometry>
        <mesh filename="package://holonome_description/meshes/rouleau.stl"/>
      </geometry>
      <origin xyz="0 0 0" rpy="0 ${pi/4} ${-pi/2}"/>
    </collision>
  </link>

  <joint name="rouleau_left4_joint" type="continuous">
    <parent link="wheel_left"/>
    <child link="rouleau_left4"/>
    <origin xyz="7.4 12.24 12.24" rpy="0 0 0"/>
    <axis xyz="0 1 -1"/>
  </joint>
  <link name="rouleau_left4">
    <visual>
      <geometry>
        <mesh filename="package://holonome_description/meshes/rouleau.stl"/>
      </geometry>
      <origin xyz="0 0 0" rpy="0 ${-pi/4} ${-pi/2}"/>
    </visual>
    <collision>
      <geometry>
        <mesh filename="package://holonome_description/meshes/rouleau.stl"/>
      </geometry>
      <origin xyz="0 0 0" rpy="0 ${pi/4} ${-pi/2}"/>
    </collision>
  </link>
  
  <joint name="rouleau_left5_joint" type="continuous">
    <parent link="wheel_left"/>
    <child link="rouleau_left5"/>
    <origin xyz="-3.8 0 17.31" rpy="0 0 0"/>
    <axis xyz="0 1 0"/>
  </joint>
  <link name="rouleau_left5">
    <visual>
      <geometry>
        <mesh filename="package://holonome_description/meshes/rouleau.stl"/>
      </geometry>
      <origin xyz="0 0 0" rpy="0 0 ${pi/2}"/>
    </visual>
    <collision>
      <geometry>
        <mesh filename="package://holonome_description/meshes/rouleau.stl"/>
      </geometry>
      <origin xyz="0 0 0" rpy="0 0 ${pi/2}"/>
    </collision>
  </link>

  <joint name="rouleau_left6_joint" type="continuous">
    <parent link="wheel_left"/>
    <child link="rouleau_left6"/>
    <origin xyz="-3.8 17.31 0" rpy="0 0 0"/>
    <axis xyz="0 0 1"/>
  </joint>
  <link name="rouleau_left6">
    <visual>
      <geometry>
        <mesh filename="package://holonome_description/meshes/rouleau.stl"/>
      </geometry>
      <origin xyz="0 0 0" rpy="0 ${pi/2} 0"/>
    </visual>
    <collision>
      <geometry>
        <mesh filename="package://holonome_description/meshes/rouleau.stl"/>
      </geometry>
      <origin xyz="0 0 0" rpy="0 ${pi/2} 0"/>
    </collision>
  </link>

  <joint name="rouleau_left7_joint" type="continuous">
    <parent link="wheel_left"/>
    <child link="rouleau_left7"/>
    <origin xyz="-3.8 0 -17.31" rpy="0 0 0"/>
    <axis xyz="0 1 0"/>
  </joint>
  <link name="rouleau_left7">
    <visual>
      <geometry>
        <mesh filename="package://holonome_description/meshes/rouleau.stl"/>
      </geometry>
      <origin xyz="0 0 0" rpy="0 0 ${pi/2}"/>
    </visual>
    <collision>
      <geometry>
        <mesh filename="package://holonome_description/meshes/rouleau.stl"/>
      </geometry>
      <origin xyz="0 0 0" rpy="0 0 ${pi/2}"/>
    </collision>
  </link>

  <joint name="rouleau_left8_joint" type="continuous">
    <parent link="wheel_left"/>
    <child link="rouleau_left8"/>
    <origin xyz="-3.8 -17.31 0" rpy="0 0 0"/>
    <axis xyz="0 0 1"/>
  </joint>
  <link name="rouleau_left8">
    <visual>
      <geometry>
        <mesh filename="package://holonome_description/meshes/rouleau.stl"/>
      </geometry>
      <origin xyz="0 0 0" rpy="0 ${pi/2} 0"/>
    </visual>
    <collision>
      <geometry>
        <mesh filename="package://holonome_description/meshes/rouleau.stl"/>
      </geometry>
      <origin xyz="0 0 0" rpy="0 ${pi/2} 0"/>
    </collision>
  </link>

  <joint name="wheel_right_joint" type="continuous">
    <parent link="base_link"/>
    <child link="wheel_right"/>
    <origin xyz="-58.6 -101.5 -21.4" rpy="0 0 ${-pi*2/3}"/>
    <axis xyz="${cos(pi*2/3)} ${sin(pi*2/3)} 0"/>
  </joint>

  <link name="wheel_right">
    <visual>
      <geometry>
        <mesh filename="package://holonome_description/meshes/roue.stl"/>
      </geometry>
      <origin xyz="0 0 0" rpy="0 ${pi/2} 0"/>
    </visual>
    <collision>
      <geometry>
        <mesh filename="package://holonome_description/meshes/roue.stl"/>
      </geometry>
      <origin xyz="0 0 0" rpy="0 ${pi/2} 0"/>
    </collision>
    <!--
    <inertial>
      <origin xyz="0.0 0 0."/>
      <mass value="0.5"/> 
      <inertia ixx="0.01" ixy="0.0" ixz="0.0"
                iyy="0.01" iyz="0.0" 
                izz="0.03" />
    </inertial>
    -->
  </link>
  
  

  <joint name="rouleau_right1_joint" type="continuous">
    <parent link="wheel_right"/>
    <child link="rouleau_right1"/>
    <origin xyz="7.4 12.24 -12.24" rpy="0 0 0"/>
    <axis xyz="0 1 1"/>
  </joint>
  <link name="rouleau_right1">
    <visual>
      <geometry>
        <mesh filename="package://holonome_description/meshes/rouleau.stl"/>
      </geometry>
      <origin xyz="0 0 0" rpy="0 ${pi/4} ${-pi/2}"/>
    </visual>
    <collision>
      <geometry>
        <mesh filename="package://holonome_description/meshes/rouleau.stl"/>
      </geometry>
      <origin xyz="0 0 0" rpy="0 ${pi/4} ${-pi/2}"/>
    </collision>
  </link>

  <joint name="rouleau_right2_joint" type="continuous">
    <parent link="wheel_right"/>
    <child link="rouleau_right2"/>
    <origin xyz="7.4 -12.24 -12.24" rpy="0 0 0"/>
    <axis xyz="0 1 -1"/>
  </joint>
  <link name="rouleau_right2">
    <visual>
      <geometry>
        <mesh filename="package://holonome_description/meshes/rouleau.stl"/>
      </geometry>
      <origin xyz="0 0 0" rpy="0 ${-pi/4} ${-pi/2}"/>
    </visual>
    <collision>
      <geometry>
        <mesh filename="package://holonome_description/meshes/rouleau.stl"/>
      </geometry>
      <origin xyz="0 0 0" rpy="0 ${-pi/4} ${-pi/2}"/>
    </collision>
  </link>

  <joint name="rouleau_right3_joint" type="continuous">
    <parent link="wheel_right"/>
    <child link="rouleau_right3"/>
    <origin xyz="7.4 -12.24 12.24" rpy="0 0 0"/>
    <axis xyz="0 1 1"/>
  </joint>
  <link name="rouleau_right3">
    <visual>
      <geometry>
        <mesh filename="package://holonome_description/meshes/rouleau.stl"/>
      </geometry>
      <origin xyz="0 0 0" rpy="0 ${pi/4} ${-pi/2}"/>
    </visual>
    <collision>
      <geometry>
        <mesh filename="package://holonome_description/meshes/rouleau.stl"/>
      </geometry>
      <origin xyz="0 0 0" rpy="0 ${pi/4} ${-pi/2}"/>
    </collision>
  </link>

  <joint name="rouleau_right4_joint" type="continuous">
    <parent link="wheel_right"/>
    <child link="rouleau_right4"/>
    <origin xyz="7.4 12.24 12.24" rpy="0 0 0"/>
    <axis xyz="0 1 -1"/>
  </joint>
  <link name="rouleau_right4">
    <visual>
      <geometry>
        <mesh filename="package://holonome_description/meshes/rouleau.stl"/>
      </geometry>
      <origin xyz="0 0 0" rpy="0 ${-pi/4} ${-pi/2}"/>
    </visual>
    <collision>
      <geometry>
        <mesh filename="package://holonome_description/meshes/rouleau.stl"/>
      </geometry>
      <origin xyz="0 0 0" rpy="0 ${pi/4} ${-pi/2}"/>
    </collision>
  </link>
  
  <joint name="rouleau_right5_joint" type="continuous">
    <parent link="wheel_right"/>
    <child link="rouleau_right5"/>
    <origin xyz="-3.8 0 17.31" rpy="0 0 0"/>
    <axis xyz="0 1 0"/>
  </joint>
  <link name="rouleau_right5">
    <visual>
      <geometry>
        <mesh filename="package://holonome_description/meshes/rouleau.stl"/>
      </geometry>
      <origin xyz="0 0 0" rpy="0 0 ${pi/2}"/>
    </visual>
    <collision>
      <geometry>
        <mesh filename="package://holonome_description/meshes/rouleau.stl"/>
      </geometry>
      <origin xyz="0 0 0" rpy="0 0 ${pi/2}"/>
    </collision>
  </link>

  <joint name="rouleau_right6_joint" type="continuous">
    <parent link="wheel_right"/>
    <child link="rouleau_right6"/>
    <origin xyz="-3.8 17.31 0" rpy="0 0 0"/>
    <axis xyz="0 0 1"/>
  </joint>
  <link name="rouleau_right6">
    <visual>
      <geometry>
        <mesh filename="package://holonome_description/meshes/rouleau.stl"/>
      </geometry>
      <origin xyz="0 0 0" rpy="0 ${pi/2} 0"/>
    </visual>
    <collision>
      <geometry>
        <mesh filename="package://holonome_description/meshes/rouleau.stl"/>
      </geometry>
      <origin xyz="0 0 0" rpy="0 ${pi/2} 0"/>
    </collision>
  </link>

  <joint name="rouleau_right7_joint" type="continuous">
    <parent link="wheel_right"/>
    <child link="rouleau_right7"/>
    <origin xyz="-3.8 0 -17.31" rpy="0 0 0"/>
    <axis xyz="0 1 0"/>
  </joint>
  <link name="rouleau_right7">
    <visual>
      <geometry>
        <mesh filename="package://holonome_description/meshes/rouleau.stl"/>
      </geometry>
      <origin xyz="0 0 0" rpy="0 0 ${pi/2}"/>
    </visual>
    <collision>
      <geometry>
        <mesh filename="package://holonome_description/meshes/rouleau.stl"/>
      </geometry>
      <origin xyz="0 0 0" rpy="0 0 ${pi/2}"/>
    </collision>
  </link>

  <joint name="rouleau_right8_joint" type="continuous">
    <parent link="wheel_right"/>
    <child link="rouleau_right8"/>
    <origin xyz="-3.8 -17.31 0" rpy="0 0 0"/>
    <axis xyz="0 0 1"/>
  </joint>
  <link name="rouleau_right8">
    <visual>
      <geometry>
        <mesh filename="package://holonome_description/meshes/rouleau.stl"/>
      </geometry>
      <origin xyz="0 0 0" rpy="0 ${pi/2} 0"/>
    </visual>
    <collision>
      <geometry>
        <mesh filename="package://holonome_description/meshes/rouleau.stl"/>
      </geometry>
      <origin xyz="0 0 0" rpy="0 ${pi/2} 0"/>
    </collision>
  </link>

  <transmission name="trans_front">
    <type>transmission_interface/SimpleTransmission</type>
    <joint name="wheel_front_joint">
      <hardwareInterface>hardware_interface/VelocityJointInterface</hardwareInterface>
    </joint>
    <actuator name="motor_front">
      <hardwareInterface>hardware_interface/VelocityJointInterface</hardwareInterface>
      <mechanicalReduction>1</mechanicalReduction>
    </actuator>
  </transmission>

  <transmission name="trans_left">
    <type>transmission_interface/SimpleTransmission</type>
    <joint name="wheel_left_joint">
      <hardwareInterface>hardware_interface/VelocityJointInterface</hardwareInterface>
    </joint>
    <actuator name="motor_left">
      <hardwareInterface>hardware_interface/VelocityJointInterface</hardwareInterface>
      <mechanicalReduction>1</mechanicalReduction>
    </actuator>
  </transmission>

  <transmission name="trans_right">
    <type>transmission_interface/SimpleTransmission</type>
    <joint name="wheel_right_joint">
      <hardwareInterface>hardware_interface/VelocityJointInterface</hardwareInterface>
    </joint>
    <actuator name="motor_right">
      <hardwareInterface>hardware_interface/VelocityJointInterface</hardwareInterface>
      <mechanicalReduction>1</mechanicalReduction>
    </actuator>
  </transmission>

</robot>